<?xml version="1.0" ?>
<!-- =================================================================================== -->
<!-- |    This document was autogenerated by xacro from /home/mehmet/workspace/cnc_simulation/src/robot_description/urdf/kuka_main.xacro | -->
<!-- |    EDITING THIS FILE BY HAND IS NOT RECOMMENDED                                 | -->
<!-- =================================================================================== -->
<robot name="kuka">
    <link name="world" />
    <joint name="world_fixed_joint" type="fixed">
        <origin rpy="0 0 0" xyz="0.0 0.0 0.0" />
        <parent link="world" />
        <child link="base_link" />
    </joint>
    <link name="base_link">
        <inertial>
            <origin rpy="0 0 0" xyz="0 0 0" />
            <mass value="150" />
            <inertia ixx="60" ixy="0" ixz="0" iyy="70" iyz="0" izz="100" />
        </inertial>
        <visual>
            <origin rpy="-1.570796327 0 0" xyz="0 0 0" />
            <geometry>
                <mesh filename="package://robot_description/meshes/visual/base_link.dae" />
            </geometry>
            <material name="">
                <color rgba="0.75294 0.75294 0.75294 1" />
            </material>
        </visual>
        <collision>
            <origin rpy="-1.570796327 0 0" xyz="0 0 0" />
            <geometry>
                <mesh filename="package://robot_description/meshes/collision/base_link.stl" />
            </geometry>
        </collision>
    </link>
    <joint name="joint_1" type="revolute">
        <origin rpy="0 0 0" xyz="0 0 0.33" />
        <parent link="base_link" />
        <child link="link_1" />
        <axis xyz="0 0 1" />
        <limit effort="300" lower="-3.2288592050000005" upper="3.2288592050000005" velocity="2.1467550390000003" />
    </joint>
    <link name="link_1">
        <inertial>
            <origin rpy="0 0 0" xyz="0 0 0.4" />
            <mass value="138" />
            <inertia ixx="30" ixy="0" ixz="0" iyy="50" iyz="0" izz="50" />
        </inertial>
        <visual>
            <origin rpy="0 0 0" xyz="0 0 0" />
            <geometry>
                <mesh filename="package://robot_description/meshes/visual/link_1.dae" />
            </geometry>
            <material name="">
                <color rgba="0.75294 0.75294 0.75294 1" />
            </material>
        </visual>
        <collision>
            <origin rpy="0 0 0" xyz="0 0 0" />
            <geometry>
                <mesh filename="package://robot_description/meshes/collision/link_1.stl" />
            </geometry>
        </collision>
    </link>
    <joint name="joint_2" type="revolute">
        <origin rpy="0 0 0" xyz="0.35 0 0.42" />
        <parent link="link_1" />
        <child link="link_2" />
        <axis xyz="0 1 0" />
        <limit effort="300" lower="-0.785398185" upper="1.4835299050000001" velocity="2.007128695" />
    </joint>
    <link name="link_2">
        <inertial>
            <origin rpy="0 0 0" xyz="0 0 0.44751" />
            <mass value="95" />
            <inertia ixx="40" ixy="0" ixz="0" iyy="40" iyz="0" izz="10" />
        </inertial>
        <visual>
            <origin rpy="-1.570796327 0 0" xyz="0 0 0" />
            <geometry>
                <mesh filename="package://robot_description/meshes/visual/link_2.dae" />
            </geometry>
            <material name="">
                <color rgba="0.75294 0.75294 0.75294 1" />
            </material>
        </visual>
        <collision>
            <origin rpy="0 0 0" xyz="0 0 0" />
            <geometry>
                <mesh filename="package://robot_description/meshes/collision/link_2.stl" />
            </geometry>
        </collision>
    </link>
    <joint name="joint_3" type="revolute">
        <origin rpy="0 0 0" xyz="0 0 1.25" />
        <parent link="link_2" />
        <child link="link_3" />
        <axis xyz="0 1 0" />
        <limit effort="300" lower="-3.6651915300000004" upper="1.134464045" velocity="1.954768816" />
    </joint>
    <link name="link_3">
        <inertial>
            <origin rpy="0 0 0" xyz="0.18842 0.18344 -0.042799" />
            <mass value="71" />
            <inertia ixx="1" ixy="0" ixz="0" iyy="10" iyz="0" izz="10" />
        </inertial>
        <visual>
            <origin rpy="-1.570796327 0 0" xyz="0 -0.184 0" />
            <geometry>
                <mesh filename="package://robot_description/meshes/visual/link_3.dae" />
            </geometry>
            <material name="">
                <color rgba="0.75294 0.75294 0.75294 1" />
            </material>
        </visual>
        <collision>
            <origin rpy="0 0 0" xyz="0 -0.184 0" />
            <geometry>
                <mesh filename="package://robot_description/meshes/collision/link_3.stl" />
            </geometry>
        </collision>
    </link>
    <joint name="joint_4" type="revolute">
        <origin rpy="0 0 0" xyz="0.96 0 -0.054" />
        <parent link="link_3" />
        <child link="link_4" />
        <axis xyz="1 0 0" />
        <limit effort="300" lower="-6.10865255" upper="6.10865255" velocity="3.124139447" />
    </joint>
    <link name="link_4">
        <inertial>
            <origin rpy="0 0 0" xyz="0.27146 -0.007326 0" />
            <mass value="17" />
            <inertia ixx="0.18" ixy="0" ixz="0" iyy="0.55" iyz="0" izz="0.64" />
        </inertial>
        <visual>
            <origin rpy="-1.570796327 0 0" xyz="0 0 0" />
            <geometry>
                <mesh filename="package://robot_description/meshes/visual/link_4.dae" />
            </geometry>
            <material name="">
                <color rgba="0.75294 0.75294 0.75294 1" />
            </material>
        </visual>
        <collision>
            <origin rpy="0 0 0" xyz="0 0 0" />
            <geometry>
                <mesh filename="package://robot_description/meshes/collision/link_4.stl" />
            </geometry>
        </collision>
    </link>
    <joint name="joint_5" type="revolute">
        <origin rpy="0 0 0" xyz="0.54 0 0" />
        <parent link="link_4" />
        <child link="link_5" />
        <axis xyz="0 1 0" />
        <limit effort="300" lower="-2.1816616250000003" upper="2.1816616250000003" velocity="3.0019663960000003" />
    </joint>
    <link name="link_5">
        <inertial>
            <origin rpy="0 0 0" xyz="0 0 0" />
            <mass value="7" />
            <inertia ixx="0.04" ixy="0" ixz="0" iyy="0.068" iyz="0" izz="0.068" />
        </inertial>
        <visual>
            <origin rpy="-1.570796327 0 0" xyz="0 0 0" />
            <geometry>
                <mesh filename="package://robot_description/meshes/visual/link_5.dae" />
            </geometry>
            <material name="">
                <color rgba="0.75294 0.75294 0.75294 1" />
            </material>
        </visual>
        <collision>
            <origin rpy="0 0 0" xyz="0 0 0" />
            <geometry>
                <mesh filename="package://robot_description/meshes/collision/link_5.stl" />
            </geometry>
        </collision>
    </link>
    <joint name="joint_6" type="revolute">
        <origin rpy="0 0 0" xyz="0.2 0 0" />
        <parent link="link_5" />
        <child link="link_6" />
        <axis xyz="1 0 0" />
        <limit effort="300" lower="-6.10865255" upper="6.10865255" velocity="3.8222711670000002" />
    </joint>
    <link name="link_6">
        <inertial>
            <origin rpy="0 0 0" xyz="0 0 0" />
            <mass value="0.5" />
            <inertia ixx="0.004" ixy="0" ixz="0" iyy="0.003" iyz="0" izz="0.003" />
        </inertial>
        <visual>
            <origin rpy="0 0 0" xyz="0 0 0" />
            <geometry>
                <mesh filename="package://robot_description/meshes/visual/link_6.dae" />
            </geometry>
            <material name="">
                <color rgba="0.75294 0.75294 0.75294 1" />
            </material>
        </visual>
        <collision>
            <origin rpy="0 0 0" xyz="0 0 0" />
            <geometry>
                <mesh filename="package://robot_description/meshes/collision/link_6.stl" />
            </geometry>
        </collision>
    </link>
    <joint name="gripper_joint" type="fixed">
        <parent link="link_6" />
        <child link="gripper_link" />
        <origin rpy="0 0 0" xyz="0.11 0 0" />
    </joint>
    <link name="gripper_link">
        <inertial>
            <origin rpy="0 0 0" xyz="0 0 0" />
            <mass value="0.3" />
            <inertia ixx="0.0001" ixy="0" ixz="0" iyy="0.0002" iyz="0" izz="0.0001" />
        </inertial>
        <visual>
            <origin rpy="0 0 0" xyz="0 0 0" />
            <geometry>
                <mesh filename="package://robot_description/meshes/gripper/gripper_base.dae" />
            </geometry>
        </visual>
        <collision>
            <origin rpy="0 0 0" xyz="0 0 0" />
            <geometry>
                <mesh filename="package://robot_description/meshes/gripper/gripper_base.dae" />
            </geometry>
        </collision>
    </link>
    <joint name="right_gripper_finger_joint" type="prismatic">
        <origin rpy="0 0 0" xyz="0.15 -0.0725 0" />
        <parent link="gripper_link" />
        <child link="right_gripper_finger_link" />
        <axis xyz="0 1 0" />
        <limit effort="100" lower="-0.01" upper="0.06" velocity="0.05" />
        <dynamics damping="0.7" />
    </joint>
    <link name="right_gripper_finger_link">
        <inertial>
            <origin rpy="0 0 0" xyz="0 0 0" />
            <mass value="0.1" />
            <inertia ixx="0.002" ixy="0" ixz="0" iyy="0.0002" iyz="0" izz="0.0002" />
        </inertial>
        <visual>
            <origin rpy="0 0 0" xyz="0 0 0" />
            <geometry>
                <mesh filename="package://robot_description/meshes/gripper/finger_right.dae" />
            </geometry>
        </visual>
        <collision>
            <origin rpy="0 0 0" xyz="0 0 0" />
            <geometry>
                <mesh filename="package://robot_description/meshes/gripper/finger_right_collision.dae" />
            </geometry>
        </collision>
    </link>
    <joint name="left_gripper_finger_joint" type="prismatic">
        <origin rpy="0 0 0" xyz="0.15 0.0725 0" />
        <parent link="gripper_link" />
        <child link="left_gripper_finger_link" />
        <axis xyz="0 -1 0" />
        <limit effort="100" lower="-0.01" upper="0.06" velocity="0.05" />
        <dynamics damping="0.7" />
    </joint>
    <link name="left_gripper_finger_link">
        <inertial>
            <origin rpy="0 0 0" xyz="0 0 0" />
            <mass value="0.1" />
            <inertia ixx="0.002" ixy="0" ixz="0" iyy="0.0002" iyz="0" izz="0.0002" />
        </inertial>
        <visual>
            <origin rpy="0 0 0" xyz="0 0 0" />
            <geometry>
                <mesh filename="package://robot_description/meshes/gripper/finger_left.dae" />
            </geometry>
        </visual>
        <collision>
            <origin rpy="0 0 0" xyz="0 0 0" />
            <geometry>
                <mesh filename="package://robot_description/meshes/gripper/finger_left_collision.dae" />
            </geometry>
        </collision>
    </link>
    <joint name="tcp_joint" type="fixed">
        <parent link="gripper_link" />
        <child link="tcp_link" />
        <origin rpy="0 0 0" xyz="0.2 0 0" />
    </joint>
    <link name="tcp_link" />
    <transmission name="left_finger_tran">
        <type>transmission_interface/SimpleTransmission</type>
        <joint name="left_gripper_finger_joint">
            <hardwareInterface>hardware_interface/PositionJointInterface</hardwareInterface>
        </joint>
        <actuator name="left_finger_actr">
            <hardwareInterface>hardware_interface/PositionJointInterface</hardwareInterface>
            <mechanicalReduction>1</mechanicalReduction>
        </actuator>
    </transmission>
    <transmission name="right_finger_tran">
        <type>transmission_interface/SimpleTransmission</type>
        <joint name="right_gripper_finger_joint">
            <hardwareInterface>hardware_interface/PositionJointInterface</hardwareInterface>
        </joint>
        <actuator name="right_finger_actr">
            <hardwareInterface>hardware_interface/PositionJointInterface</hardwareInterface>
            <mechanicalReduction>1</mechanicalReduction>
        </actuator>
    </transmission>
    <transmission name="J1_tran">
        <type>transmission_interface/SimpleTransmission</type>
        <joint name="joint_1">
            <hardwareInterface>hardware_interface/PositionJointInterface</hardwareInterface>
        </joint>
        <actuator name="J1_actr">
            <hardwareInterface>hardware_interface/PositionJointInterface</hardwareInterface>
            <mechanicalReduction>1</mechanicalReduction>
        </actuator>
    </transmission>
    <transmission name="J2_tran">
        <type>transmission_interface/SimpleTransmission</type>
        <joint name="joint_2">
            <hardwareInterface>hardware_interface/PositionJointInterface</hardwareInterface>
        </joint>
        <actuator name="J2_actr">
            <hardwareInterface>hardware_interface/PositionJointInterface</hardwareInterface>
            <mechanicalReduction>1</mechanicalReduction>
        </actuator>
    </transmission>
    <transmission name="J3_tran">
        <type>transmission_interface/SimpleTransmission</type>
        <joint name="joint_3">
            <hardwareInterface>hardware_interface/PositionJointInterface</hardwareInterface>
        </joint>
        <actuator name="J3_actr">
            <hardwareInterface>hardware_interface/PositionJointInterface</hardwareInterface>
            <mechanicalReduction>1</mechanicalReduction>
        </actuator>
    </transmission>
    <transmission name="J4_tran">
        <type>transmission_interface/SimpleTransmission</type>
        <joint name="joint_4">
            <hardwareInterface>hardware_interface/PositionJointInterface</hardwareInterface>
        </joint>
        <actuator name="J4_actr">
            <hardwareInterface>hardware_interface/PositionJointInterface</hardwareInterface>
            <mechanicalReduction>1</mechanicalReduction>
        </actuator>
    </transmission>
    <transmission name="J5_tran">
        <type>transmission_interface/SimpleTransmission</type>
        <joint name="joint_5">
            <hardwareInterface>hardware_interface/PositionJointInterface</hardwareInterface>
        </joint>
        <actuator name="J5_actr">
            <hardwareInterface>hardware_interface/PositionJointInterface</hardwareInterface>
            <mechanicalReduction>1</mechanicalReduction>
        </actuator>
    </transmission>
    <transmission name="J6_tran">
        <type>transmission_interface/SimpleTransmission</type>
        <joint name="joint_6">
            <hardwareInterface>hardware_interface/PositionJointInterface</hardwareInterface>
        </joint>
        <actuator name="J6_actr">
            <hardwareInterface>hardware_interface/PositionJointInterface</hardwareInterface>
            <mechanicalReduction>1</mechanicalReduction>
        </actuator>
    </transmission>
    <!-- Gazebo ROS Control Plugin -->
    <gazebo>
        <plugin filename="libgazebo_ros_control.so" name="gazebo_ros_control">
            <robotNamespace>/</robotNamespace>
        </plugin>
    </gazebo>
    <!-- Gazebo Link Attach Plugin -->
    <!-- <gazebo>
      <plugin name="ros_link_attacher_plugin" filename="libgazebo_ros_link_attacher.so"/>
    </gazebo> -->
</robot>

