<?xml version="1.0"?>

<robot xmlns:xacro="http://wiki.ros.org/xacro">

  <xacro:macro name="gripper" params="end_tool_link">

    <joint name="gripper_joint" type="fixed">
      <parent link="${end_tool_link}" />
      <child link="gripper_link" />
      <origin rpy="0 0 0" xyz="0.11 0 0" />
    </joint>

    <link name="gripper_link">
      <inertial>
        <origin rpy="0 0 0" xyz="0 0 0"/>
        <mass value="0.3"/>
        <inertia ixx="0.0001" ixy="0" ixz="0" iyy="0.0002" iyz="0" izz="0.0001"/>
      </inertial>
      <visual>
        <origin rpy="0 0 0" xyz="0 0 0"/>
        <geometry>
          <mesh filename="package://robot_description/meshes/gripper/gripper_base.dae"/>
        </geometry>
      </visual>
      <collision>
        <origin rpy="0 0 0" xyz="0 0 0"/>
        <geometry>
          <mesh filename="package://robot_description/meshes/gripper/gripper_base.dae"/>
        </geometry>
      </collision>
    </link>

    <joint name="right_gripper_finger_joint" type="prismatic">
      <origin rpy="0 0 0" xyz="0.15 -0.0725 0"/>
      <parent link="gripper_link"/>
      <child link="right_gripper_finger_link"/>
      <axis xyz="0 1 0"/>
      <limit effort="100" lower="-0.01" upper="0.06" velocity="0.05"/>
      <dynamics damping="0.7"/>
    </joint>

    <link name="right_gripper_finger_link">
      <inertial>
        <origin rpy="0 0 0" xyz="0 0 0"/>
        <mass value="0.1"/>
        <inertia ixx="0.002" ixy="0" ixz="0" iyy="0.0002" iyz="0" izz="0.0002"/>
      </inertial>
      <visual>
        <origin rpy="0 0 0" xyz="0 0 0"/>
        <geometry>
          <mesh filename="package://robot_description/meshes/gripper/finger_right.dae"/>
        </geometry>
      </visual>
      <collision>
        <origin rpy="0 0 0" xyz="0 0 0"/>
        <geometry>
          <mesh filename="package://robot_description/meshes/gripper/finger_right_collision.dae"/>
        </geometry>
      </collision>
    </link>

    <joint name="left_gripper_finger_joint" type="prismatic">
      <origin rpy="0 0 0" xyz="0.15 0.0725 0"/>
      <parent link="gripper_link"/>
      <child link="left_gripper_finger_link"/>
      <axis xyz="0 -1 0"/>
      <limit effort="100" lower="-0.01" upper="0.06" velocity="0.05"/>
      <dynamics damping="0.7"/>
    </joint>

    <link name="left_gripper_finger_link">
      <inertial>
        <origin rpy="0 0 0" xyz="0 0 0"/>
        <mass value="0.1"/>
        <inertia ixx="0.002" ixy="0" ixz="0" iyy="0.0002" iyz="0" izz="0.0002"/>
      </inertial>
      <visual>
        <origin rpy="0 0 0" xyz="0 0 0"/>
        <geometry>
          <mesh filename="package://robot_description/meshes/gripper/finger_left.dae"/>
        </geometry>
      </visual>
      <collision>
        <origin rpy="0 0 0" xyz="0 0 0"/>
        <geometry>
          <mesh filename="package://robot_description/meshes/gripper/finger_left_collision.dae"/>
        </geometry>
      </collision>
    </link>

    <joint name="tcp_joint" type="fixed">
      <parent link="gripper_link" />
      <child link="tcp_link" />
      <origin rpy="0 0 0" xyz="0.2 0 0" />
    </joint>

    <link name="tcp_link" />


    
    <transmission name="left_finger_tran">
      <type>transmission_interface/SimpleTransmission</type>
      <joint name="left_gripper_finger_joint">
        <hardwareInterface>hardware_interface/PositionJointInterface</hardwareInterface>
      </joint>
      <actuator name="left_finger_actr">
        <hardwareInterface>hardware_interface/PositionJointInterface</hardwareInterface>
        <mechanicalReduction>1</mechanicalReduction>
      </actuator>
    </transmission>

    <transmission name="right_finger_tran">
      <type>transmission_interface/SimpleTransmission</type>
      <joint name="right_gripper_finger_joint">
        <hardwareInterface>hardware_interface/PositionJointInterface</hardwareInterface>
      </joint>
      <actuator name="right_finger_actr">
        <hardwareInterface>hardware_interface/PositionJointInterface</hardwareInterface>
        <mechanicalReduction>1</mechanicalReduction>
      </actuator>
    </transmission>


  </xacro:macro>
</robot>